<?xml version="1.0" encoding="utf-8"?>
<!-- This URDF was automatically created by SolidWorks to URDF Exporter! Originally created by Stephen Brawner (brawner@gmail.com) 
     Commit Version: 1.6.0-1-g15f4949  Build Version: 1.6.7594.29634
     For more information, please see http://wiki.ros.org/sw_urdf_exporter -->
<robot
  name="ricMonk">
  
	<link
	name="Base">
		<inertial>
		<origin
		xyz="0.0536 0.69428 -0.16917"
		rpy="0 0 0" />
		<mass
		value="5.9209" />
		<inertia
		ixx="0.86611"
		ixy="3.0201E-12"
		ixz="-8.3865E-08"
		iyy="0.13388"
		iyz="2.0135E-12"
		izz="0.76254" />
		</inertial>
		<visual>
		<origin
		xyz="0 0 0"
		rpy="0 0 0" />
		<geometry>
		<mesh
		filename="meshes/Base.obj" />
		</geometry>
		<material
		name="">
		<color
		rgba="1 0.70980 0.50196 0.8" />
		</material>
		</visual>
	</link>  
	
	<joint name="base_weld" type="fixed">
	      <origin
	      xyz="0 0 0"
	      rpy="0 0 0" /> 
	      <parent link="world"/>
	      <child link="Base"/>
  	</joint>  
  
	<link
	name="stick_2">
		<inertial>
		<origin
			xyz="0.0536 0 0"
			rpy="0 0 0" />
			<mass
			value="0.062168" />
		<inertia
		ixx="4.4463E-06"
		ixy="-1.0251E-21"
		ixz="1.5345E-20"
		iyy="0.00084889"
		iyz="-2.4293E-22"
		izz="0.00084889" />
		</inertial>
		<visual>
			<origin
			xyz="0 0 0"
			rpy="0 0 0" />
			<geometry>
			<mesh
			  filename="meshes/stick_2.obj" />
			</geometry>
			<material
			name="">
			<color
			  rgba="1 1 1 1" />
			</material>
		</visual>
	</link>
  

	<joint
	name="stick_2"
	type="fixed">
		<origin
		xyz="0 0.34 0"
		rpy="0 0 0" />
		<parent
		link="Base" />
		<child
		link="stick_2" />
		<axis
		xyz="0 0 0" />
	</joint>  
  
	<link
	name="stick_1">
		<inertial>
			<origin
			xyz="0 0 0"
			rpy="0 0 0" />
			<mass
			value="0" />
			<inertia
			ixx="0"
			ixy="0"
			ixz="0"
			iyy="0"
			iyz="0"
			izz="0" />
		</inertial>
		<visual>
			<origin
			xyz="0 0 0"
			rpy="0 0 0" />
			<geometry>
			<mesh
			  filename="meshes/stick_1.obj" />
			</geometry>
			<material
			name="">
			<color
			  rgba="1 1 1 1" />
		</material>
		</visual>
	</link>
	<joint
	name="stick_1"
	type="fixed">
		<origin
		xyz="0 -0.34 0"
		rpy="0 0 0" />
		<parent
		link="Base" />
		<child
		link="stick_1" />
		<axis
		xyz="0 0 0" />
	</joint>
  
	<link
	name="stick_0">
		<inertial>
			<origin
			xyz="0 0 0"
			rpy="0 0 0" />
			<mass
			value="0" />
			<inertia
			ixx="0"
			ixy="0"
			ixz="0"
			iyy="0"
			iyz="0"
			izz="0" />
			</inertial>
		<visual>
			<origin
			xyz="0 0 0"
			rpy="0 0 0" />
			<geometry>
			<mesh
			  filename="meshes/stick_0.obj" />
			</geometry>
			<material
			name="">
			<color
			  rgba="1 1 1 1" />
			</material>
		</visual>
	</link>
	<joint
	name="stick_0"
	type="fixed">
		<origin
		xyz="0 0 0"
		rpy="0 0 0" />
		<parent
		link="Base" />
		<child
		link="stick_0" />
		<axis
		xyz="0 0 0" />
	</joint>
  
	<link
	name="hook_1">
	<inertial>
		<origin
		xyz="-0.00077047 0.16959 -0.022094"
		rpy="0 0 0" />
		<mass
		value="0.31253" />
		<inertia
		ixx="0.00099006"
		ixy="6.8261E-06"
		ixz="1.0342E-10"
		iyy="0.00036755"
		iyz="-4.7577E-06"
		izz="0.00069232" />
	</inertial>
	<visual>
		<origin
		xyz="0 0 0"
		rpy="0 0 0" />
		<geometry>
		<mesh
		  filename="meshes/hook_1.obj" />
		</geometry>
		<material
		name="">
		<color
		  rgba="0.96078 0.15294 0.15294 0.8" />
		</material>
	</visual>
	<!--
	<collision>
		<origin
		xyz="0 0 0"
		rpy="0 0 0" />
		<geometry>
		<mesh
		  filename="meshes/hook_1.obj" />
		</geometry>
	</collision>
	-->
	</link>
	
	<link
	name="tail">
		<inertial>
			<origin
				xyz="-0.0056009765606122 0.182449040804017 0.00254813231558806"
				rpy="0 0 0" />
			      <mass
				value="2.63096785521702" />
			      <inertia
				ixx="0.00523785541666047"
				ixy="5.87184699597149E-07"
				ixz="-4.07133795898078E-07"
				iyy="0.00395069160539681"
				iyz="-1.24226112383513E-06"
				izz="0.00309094774503178" />
			</inertial>
		<visual>
			<origin
			xyz="0 0 0"
			rpy="0 0 0" />
			<geometry>
			<mesh
			  filename="meshes/tail.obj" />
			</geometry>
			<material
			name="">
			<color
			  rgba="0.42352 0.96078 0.12594 0.8" />
			</material>
		</visual>
		<!--
		<collision>
			<origin
			xyz="0 0 0"
			rpy="0 0 0" />
			<geometry>
			<mesh
			  filename="meshes/tail.obj" />
			</geometry>
		</collision>
		-->
	</link>
  
	<link
	name="link2">
		<inertial>
			<origin
			xyz="-0.0011371 0.089177 -1.9429E-16"
			rpy="0 0 0" />
			<mass
			value="0.140647941711974" />
			<inertia
			ixx="0.0008365"
			ixy="-6.8246E-06"
			ixz="-2.7105E-20"
			iyy="0.00032416"
			iyz="-1.152E-19"
			izz="0.00056305" />
			</inertial>
		<visual>
			<origin
			xyz="0 0 0"
			rpy="0 0 0" />
			<geometry>
			<mesh
			  filename="meshes/link2.obj" />
			</geometry>
			<material
			name="">
			<color
			  rgba="0.15294 0.67450 0.96078 0.8" />
			</material>
		</visual>
		<!--
		<collision>
			<origin
			xyz="0 0 0"
			rpy="0 0 0" />
			<geometry>
			<mesh
			  filename="meshes/link2.obj" />
			</geometry>
		</collision>
		-->
	</link>

	<link
	name="hook_2">
		<inertial>
			<origin
			xyz="-1.4364E-07 0.035208 -0.027189"
			rpy="0 0 0" />
			<mass
			value="0.171894025592926" />
			<inertia
			ixx="0.00015356"
			ixy="1.4986E-09"
			ixz="1.0342E-10"
			iyy="4.3392E-05"
			iyz="-4.7577E-06"
			izz="0.00012928" />
			</inertial>
		<visual>
			<origin
			xyz="0 0 0"
			rpy="0 0 0" />
			<geometry>
			<mesh
			  filename="meshes/hook_2.obj" />
			</geometry>
			<material
			name="">
			<color
			  rgba="0.15294 0.67450 0.96078 0.8" />
			</material>
		</visual>
		<!--
		<collision>
			<origin
			xyz="0 0 0"
			rpy="0 0 0" />
			<geometry>
			<mesh
			  filename="meshes/hook_2.obj" />
			</geometry>
		</collision>
		-->
	</link>
  
	<joint
	name="virtual_fixed_link"
	type="fixed">
		<origin
		xyz="0.00054999999999894 0.314008861212629 0.0200000000000001"
		rpy="0 0 -3.14159265358979" />
		<parent
		link="link2" />
		<child
		link="hook_2" />
		<axis
		xyz="0 0 0" />
	</joint>

	<joint
	name="virtul_joint_hook_1"
	type="revolute">
		<origin
		xyz="0 0 0"
		rpy="-1.5708 0 0" />
		<parent
		link="Base" />
		<child
		link="hook_1" />
		<axis
		xyz="1 0 0" />
		<limit
		lower="-3.1415926"
		upper="3.1415926"
		effort="16"
		velocity="43" />
	</joint>
  
	<joint
	name="Joint1"
	type="revolute">
		<origin
		xyz="0.0365499999999668 0.31400886121263 -0.019999999999951"
		rpy="-3.14159265358979 0 3.14159265358979" />
		<parent
		link="hook_1" />
		<child
		link="tail" />
		<axis
		xyz="-1 0 0" />
		<limit
		lower="-3.1415926"
		upper="3.1415926"
		effort="16"
		velocity="43" />
	</joint>
	 <!--
	<joint
	name="Joint2"
	type="revolute">
		<origin
		xyz="0.0730499999999658 0.31400886121263 -0.0199999999999525"
		rpy="-3.14159265358979 0 3.14159265358979" />
		<parent
		link="hook_1" />
		<child
		link="link2" />
		<axis
		xyz="-1 0 0" />
		<limit
		lower="-3.1415926"
		upper="3.1415926"
		effort="16"
		velocity="43" />
	</joint>
	-->
	
	<joint
	name="Joint3"
	type="revolute">
		<origin
		xyz="-0.0365 0 0"
		rpy="0 0 0" />
		<parent
		link="tail" />
		<child
		link="link2" />
		<axis
		xyz="-1 0 0" />
		<limit
		lower="-3.1415926"
		upper="3.1415926"
		effort="16"
		velocity="43" />
	</joint>	
 
	<transmission type="SimpleTransmission" name="hook1_tail">
		<actuator name="Joint1"/>
		<joint name="Joint1"/>
		<mechanicalReduction>1</mechanicalReduction>
	</transmission>  
	 <!--
	<transmission type="SimpleTransmission" name="hook1_hook2">
		<actuator name="Joint2"/>
		<joint name="Joint2"/>
		<mechanicalReduction>1</mechanicalReduction>
	</transmission> 
	-->
	<transmission type="SimpleTransmission" name="tail_hook2">
		<actuator name="Joint3"/>
		<joint name="Joint3"/>
		<mechanicalReduction>1</mechanicalReduction>
	</transmission>  
</robot>
